2025-07-17 20:50:04,008 INFO    MainThread:3614947 [wandb_init.py:setup_run_log_directory():703] Logging user logs to /home/yang/Work/mobilevit-pytorch/wandb/run-20250717_205004-6b76g3hl/logs/debug.log
2025-07-17 20:50:04,008 INFO    MainThread:3614947 [wandb_init.py:setup_run_log_directory():704] Logging internal logs to /home/yang/Work/mobilevit-pytorch/wandb/run-20250717_205004-6b76g3hl/logs/debug-internal.log
2025-07-17 20:50:04,008 INFO    MainThread:3614947 [wandb_init.py:init():830] calling init triggers
2025-07-17 20:50:04,008 INFO    MainThread:3614947 [wandb_init.py:init():835] wandb.init called with sweep_config: {}
config: {'_wandb': {}}
2025-07-17 20:50:04,008 INFO    MainThread:3614947 [wandb_init.py:init():871] starting backend
2025-07-17 20:50:04,009 INFO    MainThread:3614947 [wandb_init.py:init():874] sending inform_init request
2025-07-17 20:50:04,009 INFO    MainThread:3614947 [wandb_init.py:init():882] backend started and connected
2025-07-17 20:50:04,009 DEBUG   MainThread:3614947 [config_util.py:dict_from_config_file():70] no default config file found in config-defaults.yaml
2025-07-17 20:50:04,009 INFO    MainThread:3614947 [wandb_init.py:init():953] updated telemetry
2025-07-17 20:50:04,011 INFO    MainThread:3614947 [wandb_init.py:init():977] communicating run to backend with 90.0 second timeout
2025-07-17 20:50:35,251 INFO    Thread-2 (wrapped_target):3614947 [retry.py:__call__():173] [no run ID] Retry attempt failed:
Traceback (most recent call last):
  File "/home/yang/miniconda3/envs/cvnets/lib/python3.10/site-packages/urllib3/connection.py", line 198, in _new_conn
    sock = connection.create_connection(
  File "/home/yang/miniconda3/envs/cvnets/lib/python3.10/site-packages/urllib3/util/connection.py", line 85, in create_connection
    raise err
  File "/home/yang/miniconda3/envs/cvnets/lib/python3.10/site-packages/urllib3/util/connection.py", line 73, in create_connection
    sock.connect(sa)
TimeoutError: timed out

The above exception was the direct cause of the following exception:

Traceback (most recent call last):
  File "/home/yang/miniconda3/envs/cvnets/lib/python3.10/site-packages/urllib3/connectionpool.py", line 787, in urlopen
    response = self._make_request(
  File "/home/yang/miniconda3/envs/cvnets/lib/python3.10/site-packages/urllib3/connectionpool.py", line 488, in _make_request
    raise new_e
  File "/home/yang/miniconda3/envs/cvnets/lib/python3.10/site-packages/urllib3/connectionpool.py", line 464, in _make_request
    self._validate_conn(conn)
  File "/home/yang/miniconda3/envs/cvnets/lib/python3.10/site-packages/urllib3/connectionpool.py", line 1093, in _validate_conn
    conn.connect()
  File "/home/yang/miniconda3/envs/cvnets/lib/python3.10/site-packages/urllib3/connection.py", line 753, in connect
    self.sock = sock = self._new_conn()
  File "/home/yang/miniconda3/envs/cvnets/lib/python3.10/site-packages/urllib3/connection.py", line 207, in _new_conn
    raise ConnectTimeoutError(
urllib3.exceptions.ConnectTimeoutError: (<urllib3.connection.HTTPSConnection object at 0x747271cfc040>, 'Connection to api.wandb.ai timed out. (connect timeout=20)')

The above exception was the direct cause of the following exception:

Traceback (most recent call last):
  File "/home/yang/miniconda3/envs/cvnets/lib/python3.10/site-packages/requests/adapters.py", line 667, in send
    resp = conn.urlopen(
  File "/home/yang/miniconda3/envs/cvnets/lib/python3.10/site-packages/urllib3/connectionpool.py", line 841, in urlopen
    retries = retries.increment(
  File "/home/yang/miniconda3/envs/cvnets/lib/python3.10/site-packages/urllib3/util/retry.py", line 519, in increment
    raise MaxRetryError(_pool, url, reason) from reason  # type: ignore[arg-type]
urllib3.exceptions.MaxRetryError: HTTPSConnectionPool(host='api.wandb.ai', port=443): Max retries exceeded with url: /graphql (Caused by ConnectTimeoutError(<urllib3.connection.HTTPSConnection object at 0x747271cfc040>, 'Connection to api.wandb.ai timed out. (connect timeout=20)'))

During handling of the above exception, another exception occurred:

Traceback (most recent call last):
  File "/home/yang/miniconda3/envs/cvnets/lib/python3.10/site-packages/wandb/sdk/lib/retry.py", line 134, in __call__
    result = self._call_fn(*args, **kwargs)
  File "/home/yang/miniconda3/envs/cvnets/lib/python3.10/site-packages/wandb/sdk/internal/internal_api.py", line 397, in execute
    return self.client.execute(*args, **kwargs)  # type: ignore
  File "/home/yang/miniconda3/envs/cvnets/lib/python3.10/site-packages/wandb/vendor/gql-0.2.0/wandb_gql/client.py", line 52, in execute
    result = self._get_result(document, *args, **kwargs)
  File "/home/yang/miniconda3/envs/cvnets/lib/python3.10/site-packages/wandb/vendor/gql-0.2.0/wandb_gql/client.py", line 60, in _get_result
    return self.transport.execute(document, *args, **kwargs)
  File "/home/yang/miniconda3/envs/cvnets/lib/python3.10/site-packages/wandb/sdk/lib/gql_request.py", line 58, in execute
    request = self.session.post(self.url, **post_args)
  File "/home/yang/miniconda3/envs/cvnets/lib/python3.10/site-packages/requests/sessions.py", line 637, in post
    return self.request("POST", url, data=data, json=json, **kwargs)
  File "/home/yang/miniconda3/envs/cvnets/lib/python3.10/site-packages/requests/sessions.py", line 589, in request
    resp = self.send(prep, **send_kwargs)
  File "/home/yang/miniconda3/envs/cvnets/lib/python3.10/site-packages/requests/sessions.py", line 703, in send
    r = adapter.send(request, **kwargs)
  File "/home/yang/miniconda3/envs/cvnets/lib/python3.10/site-packages/requests/adapters.py", line 688, in send
    raise ConnectTimeout(e, request=request)
requests.exceptions.ConnectTimeout: HTTPSConnectionPool(host='api.wandb.ai', port=443): Max retries exceeded with url: /graphql (Caused by ConnectTimeoutError(<urllib3.connection.HTTPSConnection object at 0x747271cfc040>, 'Connection to api.wandb.ai timed out. (connect timeout=20)'))
2025-07-17 20:51:01,436 WARNING MainThread:3614947 [wandb_init.py:init():1610] [no run ID] interrupted
Traceback (most recent call last):
  File "/home/yang/miniconda3/envs/cvnets/lib/python3.10/site-packages/wandb/sdk/wandb_init.py", line 1606, in init
    return wi.init(run_settings, run_config, run_printer)
  File "/home/yang/miniconda3/envs/cvnets/lib/python3.10/site-packages/wandb/sdk/wandb_init.py", line 996, in init
    result = wait_with_progress(
  File "/home/yang/miniconda3/envs/cvnets/lib/python3.10/site-packages/wandb/sdk/mailbox/wait_with_progress.py", line 24, in wait_with_progress
    return wait_all_with_progress(
  File "/home/yang/miniconda3/envs/cvnets/lib/python3.10/site-packages/wandb/sdk/mailbox/wait_with_progress.py", line 87, in wait_all_with_progress
    return asyncio_compat.run(progress_loop_with_timeout)
  File "/home/yang/miniconda3/envs/cvnets/lib/python3.10/site-packages/wandb/sdk/lib/asyncio_compat.py", line 30, in run
    return future.result()
  File "/home/yang/miniconda3/envs/cvnets/lib/python3.10/concurrent/futures/_base.py", line 453, in result
    self._condition.wait(timeout)
  File "/home/yang/miniconda3/envs/cvnets/lib/python3.10/threading.py", line 320, in wait
    waiter.acquire()
KeyboardInterrupt
2025-07-17 20:51:02,069 INFO    MsgRouterThr:3614947 [mailbox.py:close():129] [no run ID] Closing mailbox, abandoning 2 handles.
